<?xml version="1.0" ?>
<!-- =================================================================================== -->
<!-- |    This document was autogenerated by xacro from src/my_bot/description/robot.urdf.xacro | -->
<!-- |    EDITING THIS FILE BY HAND IS NOT RECOMMENDED                                 | -->
<!-- =================================================================================== -->
<robot name="robot">
  <!-- Materials -->
  <material name="white">
    <color rgba="1 1 1 1"/>
  </material>
  <material name="black">
    <color rgba="0 0 0 1"/>
  </material>
  <material name="blue">
    <color rgba="0 0 1 1"/>
  </material>
  <material name="red">
    <color rgba="1 0 0 1"/>
  </material>
  <!-- =================== BASE LINK =================== -->
  <link name="base_link"/>
  <!-- =================== CHASSIS =================== -->
  <joint name="chassis_joint" type="fixed">
    <parent link="base_link"/>
    <child link="chassis"/>
    <origin rpy="0 0 0" xyz="-0.2 0 0.0"/>
  </joint>
  <link name="chassis">
    <visual>
      <origin rpy="0.0 0.0 0.0" xyz="0.2 0.0 0.1"/>
      <geometry>
        <box size="0.4 0.4 0.2"/>
      </geometry>
      <material name="white"/>
    </visual>
    <collision>
      <origin rpy="0.0 0.0 0.0" xyz="0.2 0.0 0.1"/>
      <geometry>
        <box size="0.4 0.4 0.2"/>
      </geometry>
    </collision>
    <inertial>
      <origin rpy="0 0 0" xyz="0.2 0.0 0.1"/>
      <mass value="0.5"/>
      <inertia ixx="0.008333333333333335" ixy="0" ixz="0" iyy="0.008333333333333335" iyz="0" izz="0.013333333333333336"/>
    </inertial>
  </link>
  <gazebo reference="chassis">
    <material>Gazebo/White</material>
  </gazebo>
  <!--LEFT FRONT WHEEL JOINT-->
  <joint name="left_front_joint" type="continuous">
    <parent link="base_link"/>
    <child link="left_front"/>
    <origin rpy="-1.5707963267948966 0 0" xyz="0.1 0.22 0.0"/>
    <axis xyz="0 0 1"/>
  </joint>
  <!--LEFT FRONT WHEEL LINK-->
  <link name="left_front">
    <visual>
      <geometry>
        <cylinder length="0.04" radius="0.075"/>
      </geometry>
      <material name="blue"/>
    </visual>
    <collision>
      <geometry>
        <cylinder length="0.04" radius="0.075"/>
      </geometry>
    </collision>
    <inertial>
      <origin rpy="0.0 0.0 0.0" xyz="0.0 0.0 0.0"/>
      <mass value="0.1"/>
      <inertia ixx="0.0001539583333333333" ixy="0" ixz="0" iyy="0.0001539583333333333" iyz="0" izz="0.00028125"/>
    </inertial>
  </link>
  <gazebo reference="left_front">
    <material>Gazebo/Blue</material>
  </gazebo>
  <!--RIGHT FRONT WHEEL JOINT-->
  <joint name="right_front_joint" type="continuous">
    <parent link="base_link"/>
    <child link="right_front"/>
    <origin rpy="1.5707963267948966 0 0" xyz="0.1 -0.22 0.0"/>
    <axis xyz="0 0 -1"/>
  </joint>
  <!--RIGHT FRONT WHEEL LINK-->
  <link name="right_front">
    <visual>
      <geometry>
        <cylinder length="0.04" radius="0.075"/>
      </geometry>
      <material name="blue"/>
    </visual>
    <collision>
      <geometry>
        <cylinder length="0.04" radius="0.075"/>
      </geometry>
    </collision>
    <inertial>
      <origin rpy="0.0 0.0 0.0" xyz="0.0 0.0 0.0"/>
      <mass value="0.1"/>
      <inertia ixx="0.0001539583333333333" ixy="0" ixz="0" iyy="0.0001539583333333333" iyz="0" izz="0.00028125"/>
    </inertial>
  </link>
  <gazebo reference="right_front">
    <material>Gazebo/Blue</material>
  </gazebo>
  <!--LEFT REAR WHEEL JOINT-->
  <joint name="left_rear_joint" type="continuous">
    <parent link="base_link"/>
    <child link="left_rear"/>
    <origin rpy="-1.5707963267948966 0 0" xyz="-0.1 0.22 0.0"/>
    <axis xyz="0 0 1"/>
  </joint>
  <!--LEFT REAR WHEEL LINK-->
  <link name="left_rear">
    <visual>
      <geometry>
        <cylinder length="0.04" radius="0.075"/>
      </geometry>
      <material name="blue"/>
    </visual>
    <collision>
      <geometry>
        <cylinder length="0.04" radius="0.075"/>
      </geometry>
    </collision>
    <inertial>
      <origin rpy="0.0 0.0 0.0" xyz="0.0 0.0 0.0"/>
      <mass value="0.1"/>
      <inertia ixx="0.0001539583333333333" ixy="0" ixz="0" iyy="0.0001539583333333333" iyz="0" izz="0.00028125"/>
    </inertial>
  </link>
  <gazebo reference="left_rear">
    <material>Gazebo/Blue</material>
  </gazebo>
  <!--RIGHT REAR WHEEL JOINT-->
  <joint name="right_rear_joint" type="continuous">
    <parent link="base_link"/>
    <child link="right_rear"/>
    <origin rpy="1.5707963267948966 0 0" xyz="-0.1 -0.22 0.0"/>
    <axis xyz="0 0 -1"/>
  </joint>
  <!--RIGHT REAR WHEEL LINK-->
  <link name="right_rear">
    <visual>
      <geometry>
        <cylinder length="0.04" radius="0.075"/>
      </geometry>
      <material name="blue"/>
    </visual>
    <collision>
      <geometry>
        <cylinder length="0.04" radius="0.075"/>
      </geometry>
    </collision>
    <inertial>
      <origin rpy="0.0 0.0 0.0" xyz="0.0 0.0 0.0"/>
      <mass value="0.1"/>
      <inertia ixx="0.0001539583333333333" ixy="0" ixz="0" iyy="0.0001539583333333333" iyz="0" izz="0.00028125"/>
    </inertial>
  </link>
  <gazebo reference="right_rear">
    <material>Gazebo/Blue</material>
  </gazebo>
  <gazebo>
    <plugin filename="libgazebo_ros_diff_drive.so" name="skid_steer_drive">
      <!-- Wheel Information -->
      <num_wheel_pairs>2</num_wheel_pairs>
      <left_joint>left_front_joint</left_joint>
      <right_joint>right_front_joint</right_joint>
      <left_joint>left_rear_joint</left_joint>
      <right_joint>right_rear_joint</right_joint>
      <wheel_separation>0.44</wheel_separation>
      <wheel_diameter>0.1</wheel_diameter>
      <!-- Limits -->
      <max_wheel_torque>500</max_wheel_torque>
      <max_wheel_acceleration>10.0</max_wheel_acceleration>
      <ros>
        <namespace>/</namespace>
        <remapping>/cmd_vel:=cmd_vel</remapping>
        <remapping>/odom:=odom</remapping>
      </ros>
      <!-- Output -->
      <update_rate>30.0</update_rate>
      <odometry_frame>odom</odometry_frame>
      <robot_base_frame>base_link</robot_base_frame>
      <publish_odom>true</publish_odom>
      <publish_odom_tf>true</publish_odom_tf>
      <publish_wheel_tf>true</publish_wheel_tf>
      <odometry_topic>odom</odometry_topic>
      <!-- <robot_base_frame>base_footprint</robot_base_frame> -->
    </plugin>
    <plugin filename="libgazebo_ros_joint_state_publisher.so" name="rover_joint_state">
      <ros>
        <remapping>~/out:=joint_states</remapping>
      </ros>
      <update_rate>30</update_rate>
      <joint_name>left_front_joint</joint_name>
      <joint_name>right_front_joint</joint_name>
      <joint_name>left_rear_joint</joint_name>
      <joint_name>right_rear_joint</joint_name>
    </plugin>
  </gazebo>
  <joint name="laser_joint" type="fixed">
    <parent link="chassis"/>
    <child link="laser_frame"/>
    <origin rpy="0 0 0" xyz="0.2 0 0.2"/>
  </joint>
  <link name="laser_frame">
    <visual>
      <geometry>
        <cylinder length="0.04" radius="0.05"/>
      </geometry>
      <material name="red"/>
    </visual>
    <collision>
      <geometry>
        <cylinder length="0.04" radius="0.05"/>
      </geometry>
    </collision>
    <inertial>
      <origin rpy="0 0 0" xyz="0 0 0"/>
      <mass value="0.2"/>
      <inertia ixx="0.0001516666666666667" ixy="0" ixz="0" iyy="0.0001516666666666667" iyz="0" izz="0.00025000000000000006"/>
    </inertial>
  </link>
  <gazebo reference="laser_frame">
    <material>Gazebo/Red</material>
    <sensor name="laser" type="ray">
      <pose> 0 0 0 0 0 0 </pose>
      <visualize>true</visualize>
      <update_rate>10</update_rate>
      <ray>
        <scan>
          <horizontal>
            <samples>360</samples>
            <min_angle>-3.14</min_angle>
            <max_angle>3.14</max_angle>
          </horizontal>
        </scan>
        <range>
          <min>0.3</min>
          <max>12</max>
        </range>
      </ray>
      <plugin filename="libgazebo_ros_ray_sensor.so" name="laser_controller">
        <ros>
          <argument>~/out:=scan</argument>
        </ros>
        <output_type>sensor_msgs/LaserScan</output_type>
        <frame_name>laser_frame</frame_name>
      </plugin>
    </sensor>
  </gazebo>
  <!--
    Macro to add a ZED camera using the zed_wrapper's zed_macro.urdf.xacro.
    This keeps the main robot file clean — call with desired parameters.
  -->
  <!-- Camera mounting point (the threaded screw hole in the bottom) -->
  <link name="zed2_camera_link"/>
  <!-- Camera Center -->
  <link name="zed2_camera_center">
    <visual>
      <origin rpy="0 0 0" xyz="0.0 0 0.0"/>
      <geometry>
        <mesh filename="file:///opt/ros/humble/share/zed_msgs/meshes/zed2.stl"/>
      </geometry>
      <material name="zed_mat">
        <color rgba="0.25 0.25 0.25 1.0"/>
      </material>
    </visual>
    <collision>
      <origin rpy="0 0 0" xyz="0.0 0 0.0"/>
      <geometry>
        <mesh filename="file:///opt/ros/humble/share/zed_msgs/meshes/zed2.stl"/>
      </geometry>
    </collision>
  </link>
  <joint name="zed2_camera_center_joint" type="fixed">
    <parent link="zed2_camera_link"/>
    <child link="zed2_camera_center"/>
    <origin rpy="0 0.05 0" xyz="0 0 0.015"/>
  </joint>
  <!-- Left Camera -->
  <link name="zed2_left_camera_frame">
  </link>
  <joint name="zed2_left_camera_joint" type="fixed">
    <parent link="zed2_camera_center"/>
    <child link="zed2_left_camera_frame"/>
    <origin rpy="0 0 0" xyz="-0.01 0.06 0"/>
  </joint>
  <link name="zed2_left_camera_frame_optical"/>
  <joint name="zed2_left_camera_optical_joint" type="fixed">
    <origin rpy="-1.5707963267948966 0.0 -1.5707963267948966" xyz="0 0 0"/>
    <parent link="zed2_left_camera_frame"/>
    <child link="zed2_left_camera_frame_optical"/>
  </joint>
  <!-- Right Camera -->
  <link name="zed2_right_camera_frame">
  </link>
  <joint name="zed2_right_camera_joint" type="fixed">
    <parent link="zed2_camera_center"/>
    <child link="zed2_right_camera_frame"/>
    <origin rpy="0 0 0" xyz="-0.01 -0.06 0"/>
  </joint>
  <link name="zed2_right_camera_frame_optical"/>
  <joint name="zed2_right_camera_optical_joint" type="fixed">
    <origin rpy="-1.5707963267948966 0.0 -1.5707963267948966" xyz="0 0 0"/>
    <parent link="zed2_right_camera_frame"/>
    <child link="zed2_right_camera_frame_optical"/>
  </joint>
  <link name="zed2_mag_link"/>
  <joint name="zed2_mag_joint" type="fixed">
    <parent link="zed2_camera_center"/>
    <child link="zed2_mag_link"/>
    <origin rpy="0 0 0" xyz="0 0 0"/>
  </joint>
  <link name="zed2_baro_link"/>
  <joint name="zed2_baro_joint" type="fixed">
    <parent link="zed2_camera_center"/>
    <child link="zed2_baro_link"/>
    <origin rpy="0 0 0" xyz="0 0 0"/>
  </joint>
  <link name="zed2_temp_left_link"/>
  <joint name="zed2_temp_left_joint" type="fixed">
    <parent link="zed2_left_camera_frame"/>
    <child link="zed2_temp_left_link"/>
    <origin rpy="0 0 0" xyz="0 0 0"/>
  </joint>
  <link name="zed2_temp_right_link"/>
  <joint name="zed2_temp_right_joint" type="fixed">
    <parent link="zed2_right_camera_frame"/>
    <child link="zed2_temp_right_link"/>
    <origin rpy="0 0 0" xyz="0 0 0"/>
  </joint>
  <!-- Attach camera to chassis to avoid multiple root links -->
  <joint name="zed2_auto_mount_joint" type="fixed">
    <parent link="chassis"/>
    <child link="zed2_camera_link"/>
    <!-- place camera at mount origin (no rotation) -->
    <origin rpy="0 0 0" xyz="0.4 0.0 0.15"/>
  </joint>
  <!-- Visible marker to show camera position in Gazebo (useful while plugins disabled) -->
  <link name="zed2_visual_marker">
    <visual>
      <origin rpy="0 0 0" xyz="0 0 0.03"/>
      <geometry>
        <box size="0.06 0.03 0.02"/>
      </geometry>
      <material name="red"/>
    </visual>
  </link>
  <joint name="zed2_visual_marker_joint" type="fixed">
    <parent link="zed2_camera_link"/>
    <child link="zed2_visual_marker"/>
    <origin rpy="0 0 0" xyz="0 0 0"/>
  </joint>
  <!-- Re-enabled Gazebo plugin blocks with conservative settings (lower resolution and update rate).
         If gzserver crashes, re-disable and enable plugins one-by-one to isolate. -->
  <!-- Left camera sensor -->
  <gazebo reference="zed2_left_camera_frame">
    <sensor name="zed2_left_camera" type="camera">
      <update_rate>5</update_rate>
      <pose>0 0 0 0 0 0</pose>
      <camera>
        <horizontal_fov>1.047</horizontal_fov>
        <image>
          <width>640</width>
          <height>360</height>
          <format>R8G8B8</format>
        </image>
        <clip>
          <near>0.1</near>
          <far>100</far>
        </clip>
      </camera>
      <plugin filename="libgazebo_ros_camera.so" name="zed2_left_cam_plugin">
        <ros>
          <namespace>/</namespace>
          <remapping>~/image_raw:=/zed2/left/image_raw</remapping>
          <remapping>~/image_rect:=/zed2/left/image_rect_color</remapping>
          <remapping>~/camera_info:=/zed2/left/camera_info</remapping>
        </ros>
        <frameName>zed2_left_camera_frame</frameName>
        <output>sensor_msgs/msg/Image</output>
      </plugin>
    </sensor>
  </gazebo>
  <!-- Right camera sensor -->
  <gazebo reference="zed2_right_camera_frame">
    <sensor name="zed2_right_camera" type="camera">
      <update_rate>5</update_rate>
      <pose>0 0 0 0 0 0</pose>
      <camera>
        <horizontal_fov>1.047</horizontal_fov>
        <image>
          <width>640</width>
          <height>360</height>
          <format>R8G8B8</format>
        </image>
        <clip>
          <near>0.1</near>
          <far>100</far>
        </clip>
      </camera>
      <plugin filename="libgazebo_ros_camera.so" name="zed2_right_cam_plugin">
        <ros>
          <namespace>/</namespace>
          <remapping>~/image_raw:=/zed2/right/image_raw</remapping>
          <remapping>~/image_rect:=/zed2/right/image_rect_color</remapping>
          <remapping>~/camera_info:=/zed2/right/camera_info</remapping>
        </ros>
        <frameName>zed2_right_camera_frame</frameName>
        <output>sensor_msgs/msg/Image</output>
      </plugin>
    </sensor>
  </gazebo>
  <!-- Depth / disparity sensor attached to camera center (produces depth/disparity topics) -->
  <gazebo reference="zed2_camera_center">
    <sensor name="zed2_depth_sensor" type="depth">
      <update_rate>5</update_rate>
      <pose>0 0 0 0 0 0</pose>
      <depth>
        <min>0.1</min>
        <max>100</max>
      </depth>
      <plugin filename="libgazebo_ros_camera.so" name="zed2_depth_plugin">
        <ros>
          <namespace>/</namespace>
          <remapping>~/depth/image_raw:=/zed2/depth/image_raw</remapping>
          <remapping>~/depth/disparity:=/zed2/depth/disparity</remapping>
          <remapping>~/depth/camera_info:=/zed2/depth/camera_info</remapping>
        </ros>
        <frameName>zed2_camera_center</frameName>
        <output>sensor_msgs/msg/Image</output>
      </plugin>
    </sensor>
  </gazebo>
</robot>
